die_tests

test_change_weight (__main__.TestDie) ... ok
test_init (__main__.TestDie) ... ok
test_roll_die (__main__.TestDie) ... ok
test_str (__main__.TestDie) ... ok

----------------------------------------------------------------------
Ran 4 tests in 0.008s

OK


game_tests
...
----------------------------------------------------------------------
Ran 3 tests in 0.004s

OK


analyzer_tests


EEE
======================================================================
ERROR: test_combo (__main__.TestAnalyzer)
----------------------------------------------------------------------
Traceback (most recent call last):
  File "/Users/tommy/NOT IN THE CLOUD/Data Science Final/analyzer_tests.py", line 9, in setUp
    self.analyzer = Analyzer(self.game)
  File "/Users/tommy/NOT IN THE CLOUD/Data Science Final/montecarlo.py", line 118, in __init__
    sample_roll = game.show_results().iloc[0]
  File "/Users/tommy/opt/anaconda3/lib/python3.9/site-packages/pandas/core/indexing.py", line 967, in __getitem__
    return self._getitem_axis(maybe_callable, axis=axis)
  File "/Users/tommy/opt/anaconda3/lib/python3.9/site-packages/pandas/core/indexing.py", line 1523, in _getitem_axis
    self._validate_integer(key, axis)
  File "/Users/tommy/opt/anaconda3/lib/python3.9/site-packages/pandas/core/indexing.py", line 1455, in _validate_integer
    raise IndexError("single positional indexer is out-of-bounds")
IndexError: single positional indexer is out-of-bounds

======================================================================
ERROR: test_face_count (__main__.TestAnalyzer)
----------------------------------------------------------------------
Traceback (most recent call last):
  File "/Users/tommy/NOT IN THE CLOUD/Data Science Final/analyzer_tests.py", line 9, in setUp
    self.analyzer = Analyzer(self.game)
  File "/Users/tommy/NOT IN THE CLOUD/Data Science Final/montecarlo.py", line 118, in __init__
    sample_roll = game.show_results().iloc[0]
  File "/Users/tommy/opt/anaconda3/lib/python3.9/site-packages/pandas/core/indexing.py", line 967, in __getitem__
    return self._getitem_axis(maybe_callable, axis=axis)
  File "/Users/tommy/opt/anaconda3/lib/python3.9/site-packages/pandas/core/indexing.py", line 1523, in _getitem_axis
    self._validate_integer(key, axis)
  File "/Users/tommy/opt/anaconda3/lib/python3.9/site-packages/pandas/core/indexing.py", line 1455, in _validate_integer
    raise IndexError("single positional indexer is out-of-bounds")
IndexError: single positional indexer is out-of-bounds

======================================================================
ERROR: test_jackpot (__main__.TestAnalyzer)
----------------------------------------------------------------------
Traceback (most recent call last):
  File "/Users/tommy/NOT IN THE CLOUD/Data Science Final/analyzer_tests.py", line 9, in setUp
    self.analyzer = Analyzer(self.game)
  File "/Users/tommy/NOT IN THE CLOUD/Data Science Final/montecarlo.py", line 118, in __init__
    sample_roll = game.show_results().iloc[0]
  File "/Users/tommy/opt/anaconda3/lib/python3.9/site-packages/pandas/core/indexing.py", line 967, in __getitem__
    return self._getitem_axis(maybe_callable, axis=axis)
  File "/Users/tommy/opt/anaconda3/lib/python3.9/site-packages/pandas/core/indexing.py", line 1523, in _getitem_axis
    self._validate_integer(key, axis)
  File "/Users/tommy/opt/anaconda3/lib/python3.9/site-packages/pandas/core/indexing.py", line 1455, in _validate_integer
    raise IndexError("single positional indexer is out-of-bounds")
IndexError: single positional indexer is out-of-bounds

----------------------------------------------------------------------
Ran 3 tests in 0.003s

FAILED (errors=3)
